Workbook

Sheet total
B1: Tabel Input-Output Indonesia Transaksi Total Atas Dasar Harga Dasar (185 Produk), 2020
B2: (Juta Rupiah)
B4: Kode | C4: Produk | D4: 1 | E4: 2 | F4: 3 | G4: 4 | H4: 5 | I4: 6 | J4: 7 | K4: 8 | L4: 9 | M4: 10 | N4: 11 | O4: 12 | P4: 13 | Q4: 14 | R4: 15 | S4: 16 | T4: 17 | U4: 18 | V4: 19 | W4: 20 | X4: 21 | Y4: 22 | Z4: 23 | AA4: 24 | AB4: 25 | AC4: 26 | AD4: 27 | AE4: 28 | AF4: 29 | AG4: 30 | AH4: 31 | AI4: 32 | AJ4: 33 | AK4: 34 | AL4: 35 | AM4: 36 | AN4: 37 | AO4: 38 | AP4: 39 | AQ4: 40 | AR4: 41 | AS4: 42 | AT4: 43 | AU4: 44 | AV4: 45 | AW4: 46 | AX4: 47 | AY4: 48 | AZ4: 49 | BA4: 50 | BB4: 51 | BC4: 52 | BD4: 53 | BE4: 54 | BF4: 55 | BG4: 56 | BH4: 57 | BI4: 58 | BJ4: 59 | BK4: 60 | BL4: 61 | BM4: 62 | BN4: 63 | BO4: 64 | BP4: 65 | BQ4: 66 | BR4: 67 | BS4: 68 | BT4: 69 | BU4: 70 | BV4: 71 | BW4: 72 | BX4: 73 | BY4: 74 | BZ4: 75 | CA4: 76 | CB4: 77 | CC4: 78 | CD4: 79 | CE4: 80 | CF4: 81 | CG4: 82 | CH4: 83 | CI4: 84 | CJ4: 85 | CK4: 86 | CL4: 87 | CM4: 88 | CN4: 89 | CO4: 90 | CP4: 91 | CQ4: 92 | CR4: 93 | CS4: 94 | CT4: 95 | CU4: 96 | CV4: 97 | CW4: 98 | CX4: 99 | CY4: 100 | CZ4: 101 | DA4: 102 | DB4: 103 | DC4: 104 | DD4: 105 | DE4: 106 | DF4: 107 | DG4: 108 | DH4: 109 | DI4: 110 | DJ4: 111 | DK4: 112 | DL4: 113 | DM4: 114 | DN4: 115 | DO4: 116 | DP4: 117 | DQ4: 118 | DR4: 119 | DS4: 120 | DT4: 121 | DU4: 122 | DV4: 123 | DW4: 124 | DX4: 125 | DY4: 126 | DZ4: 127 | EA4: 128 | EB4: 129 | EC4: 130 | ED4: 131 | EE4: 132 | EF4: 133 | EG4: 134 | EH4: 135 | EI4: 136 | EJ4: 137 | EK4: 138 | EL4: 139 | EM4: 140 | EN4: 141 | EO4: 142 | EP4: 143 | EQ4: 144 | ER4: 145 | ES4: 146 | ET4: 147 | EU4: 148 | EV4: 149 | EW4: 150 | EX4: 151 | EY4: 152 | EZ4: 153 | FA4: 154 | FB4: 155 | FC4: 156 | FD4: 157 | FE4: 158 | FF4: 159 | FG4: 160 | FH4: 161 | FI4: 162 | FJ4: 163 | FK4: 164 | FL4: 165 | FM4: 166 | FN4: 167 | FO4: 168 | FP4: 169 | FQ4: 170 | FR4: 171 | FS4: 172 | FT4: 173 | FU4: 174 | FV4: 175 | FW4: 176 | FX4: 177 | FY4: 178 | FZ4: 179 | GA4: 180 | GB4: 181 | GC4: 182 | GD4: 183 | GE4: 184 | GF4: 185 | GG4: 1800 | GH4: 3011 | GI4: 3012 | GJ4: 3020 | GK4: 3030 | GL4: 3040 | GM4: 3050 | GN4: 3060 | GO4: 3090 | GP4: 3100 | GQ4: 4011 | GR4: 4012 | GS4: 4013 | GT4: 4019 | GU4: 5011 | GV4: 5012 | GW4: 5013 | GX4: 5019 | GY4: 6090 | GZ4: 7000 | HA4: 8000
D5: Padi | E5: Jagung | F5: Ubi jalar | G5: Ubi kayu | H5: Umbi-umbian lainnya | I5: Kacang tanah | J5: Kedelai | K5: Kacang-kacangan Lainnya | L5: Padi-padian dan Bahan Makanan Lainnya | M5: Sayur-sayuran | N5: Tanaman Hias dan Holtikultura Lainnya | O5: Tebu | P5: Tembakau | Q5: Tanaman serat | R5: Hasil Perkebunan Lainnya | S5: Buah-buahan | T5: Tanaman Biofarmaka | U5: Karet | V5: Kelapa | W5: Kelapa Sawit | X5: Kopi | Y5: Teh | Z5: Kakao | AA5: Cengkeh | AB5: Jambu Mete | AC5: Ternak dan Hasil-hasilnya kecuali Susu Segar | AD5: Susu segar | AE5: Unggas dan Hasil-hasilnya | AF5: Hasil Pemeliharaan Hewan Lainnya | AG5: Jasa Pertanian, Kehutanan dan Perikanan | AH5: Kayu | AI5: Hasil Hutan Lainnya | AJ5: Ikan | AK5: Udang dan crustacea lainnya | AL5: Biota air lainnya | AM5: Rumput laut dan sejenisnya | AN5: Batubara dan lignit | AO5: Minyak Bumi | AP5: Gas Bumi dan Panas Bumi | AQ5: Pasir besi dan bijih besi | AR5: Bijih Timah | AS5: Bijih Bauksit | AT5: Bijih Tembaga | AU5: Bijih Nikel | AV5: Barang Tambang Logam Lainnya | AW5: Bijih Emas | AX5: Bijih Perak | AY5: Barang Galian Segala Jenis | AZ5: Barang Tambang Mineral Bukan Logam | BA5: Garam Kasar | BB5: Jasa pertambangan minyak bumi dan gas alam | BC5: Jasa pertambangan dan penggalian lainnya | BD5: Hasil Pemotongan Hewan | BE5: Hasil Pengolahan dan Pengawetan Daging | BF5: Ikan Kering dan Ikan Asin | BG5: Hasil Pengolahan dan Pengawetan Ikan | BH5: Hasil Pengolahan dan Pengawetan Buah-buahan dan Sayur-sayuran | BI5: Minyak Hewani dan Minyak Nabati | BJ5: Minyak kelapa dan Kopra | BK5: Makanan dan Minuman Terbuat dari Susu | BL5: Tepung Lainnya | BM5: Tepung Terigu, Pati dan Produk Pati | BN5: Hasil Penggilingan Padi dan Penyosohan Beras | BO5: Roti, Biskuit dan Sejenisnya | BP5: Gula | BQ5: Coklat dan Kembang Gula | BR5: Mie, Macaroni dan Sejenisnya | BS5: Kopi Olahan | BT5: Teh Olahan | BU5: Kedele Olahan | BV5: Makanan Lainnya | BW5: Makanan Hewan Olahan | BX5: Minuman Beralkohol | BY5: Minuman Tak Beralkohol | BZ5: Rokok | CA5: Tembakau Olahan | CB5: Benang | CC5: Tekstil | CD5: Permadani,Tali dan Penutup Lantai Lainnya | CE5: Produk Tekstil Lainnya | CF5: Barang-barang Rajutan dan Sulaman/Bordiran | CG5: Pakaian Jadi | CH5: Hasil Pengawetan dan Penyamakan Kulit | CI5: Barang-barang dari Kulit | CJ5: Alas Kaki | CK5: Kayu Gergajian dan Olahan | CL5: Kayu Lapis dan Sejenisnya | CM5: Bahan Bangunan dari Kayu | CN5: Barang-barang Lainnya dari Kayu, Gabus, Bambu dan Rotan | CO5: Bubur Kertas | CP5: Kertas | CQ5: Barang-Barang dari Kertas dan Karton | CR5: Barang Cetakan | CS5: Barang-barang Lainnya dari Bahan Bukan Logam dan Produk dari Batubara | CT5: Barang-barang Hasil Kilang Minyak dan Gas serta Produk Batubara | CU5: Kimia Dasar Kecuali Pupuk | CV5: Pupuk | CW5: Plastik, Karet dan Serat Buatan | CX5: Pestisida | CY5: Cat dan tinta cetak | CZ5: Vernis dan Lak | DA5: Sabun dan bahan pembersih | DB5: Kosmetik | DC5: Barang-barang kimia lainnya | DD5: Produk farmasi | DE5: Obat Tradisional | DF5: Ban | DG5: Karet Remah dan Karet Asap | DH5: Barang-barang Lainnya dari Karet | DI5: Barang-Barang dari Plastik | DJ5: Kaca dan Barang-barang dari Kaca | DK5: Barang-Barang dari tanah liat, keramik dan porselen | DL5: Semen | DM5: Besi dan Baja Dasar | DN5: Logam Dasar Bukan Besi | DO5: Barang-barang hasil Pengecoran logam | DP5: Bahan Bangunan dari Logam | DQ5: Senjata dan amunisi, metalurgi dan jasa pembuatan barang logam | DR5: Alat-alat dapur, pertukangan, perabot rumahtangga dan kantor dari logam | DS5: Barang-barang Logam Lainnya | DT5: Barang-barang Elektronik, Komunikasi dan Perlengkapannya | DU5: Alat Ukur, Fotografi, Optik dan Jam | DV5: Mesin Pembangkit dan Motor Listrik | DW5: Mesin Listrik dan Perlengkapannya | DX5: Baterai dan Aki | DY5: Perlengkapan Listrik Lainnya | DZ5: Alat Listrik Untuk Rumah Tangga | EA5: Mesin Penggerak Mula | EB5: Mesin untuk keperluan kantor dan akunting, dan bagian serta perlengkapannya | EC5: Mesin lainnya dan perlengkapannya | ED5: Kendaraan Bermotor Kecuali Sepeda Motor | EE5: Kapal dan Jasa Perbaikannya | EF5: Kereta Api dan Jasa Perbaikannya | EG5: Pesawat Terbang dan Jasa Perbaikannya | EH5: Alat Pengangkutan Lainnya | EI5: Sepeda Motor | EJ5: Perabotan Rumah Tangga dan Kantor Selain dari Logam | EK5: Perhiasan | EL5: Alat-Alat Musik | EM5: Alat-Alat Olahraga | EN5: Alat Permainan dan mainan anak-anak | EO5: Alat Kedokteran | EP5: Barang-barang hasil industri pengolahan lainnya | EQ5: Jasa perawatan dan perbaikan produk-produk logam pabrikan, mesin-mesin dan peralatan | ER5: Listrik | ES5: Hasil gas alam dan buatan, pengadaan uap air/air panas, udara dingin dan produk es | ET5: Pengadaan Air | EU5: Pengelolaan Sampah, Limbah dan Daur Ulang | EV5: Bangunan Tempat Tinggal dan Bukan Tempat Tinggal | EW5: Bangunan dan Instalasi Listrik, Gas, Air Minum dan Komunikasi | EX5: Prasarana Pertanian | EY5: Jalan, Jembatan, dan Pelabuhan | EZ5: Bangunan Lainnya | FA5: Perdagangan Mobil dan Sepeda Motor | FB5: Reparasi dan Perawatan Mobil dan Sepeda Motor | FC5: Perdagangan selain Mobil dan Sepeda Motor | FD5: Jasa Angkutan Rel | FE5: Jasa Angkutan Darat Selain Angkutan Rel | FF5: Jasa Angkutan Laut | FG5: Jasa Angkutan Sungai danau dan Penyeberangan | FH5: Jasa Angkutan Udara | FI5: Jasa Penunjang Angkutan | FJ5: Jasa Pos dan Kurir | FK5: Penyediaan Akomodasi | FL5: Penyediaan Makan dan Minum | FM5: Hasil-hasil Penerbitan | FN5: Jasa Penyiaran dan pemrograman, Film dan Hasil Perekaman Suara | FO5: Jasa Telekomunikasi | FP5: Jasa Konsultasi komputer dan teknologi informasi | FQ5: Jasa Keuangan Perbankan | FR5: Jasa asuransi | FS5: Jasa dana Pensiun | FT5: Jasa Lembaga Keuangan Lainnya | FU5: Jasa Real Estate | FV5: Jasa Profesional, Ilmiah dan Teknis | FW5: Jasa Persewaan dan Jasa Penunjang Usaha | FX5: Jasa Pemerintahan Umum | FY5: Jasa Pendidikan Pemerintah | FZ5: Jasa Kesehatan Pemerintah | GA5: Jasa Pemerintahan Lainnya | GB5: Jasa Pendidikan Swasta | GC5: Jasa Kesehatan dan Kegiatan Sosial Swasta | GD5: Jasa Kesenian, Hiburan dan Rekreasi | GE5: Reparasi Barang Rumahtangga dan Pribadi Lainnya | GF5: Jasa Lainnya | GG5: Total Permintaan Antara | GH5: Konsumsi Rumah Tangga | GI5: Konsumsi LNPRT | GJ5: Konsumsi Pemerintah | GK5: Pembentukan Modal Tetap Bruto | GL5: Perubahan Inventori | GM5: Ekspor Barang (F.o.b) | GN5: Ekspor Jasa | GO5: Total Permintaan Akhir | GP5: Total Permintaan | GQ5: Impor Barang (c.i.f) | GR5: Impor Jasa | GS5: Adjustment (i.f) | GT5: Total Impor | GU5: Marjin Perdagangan Besar | GV5: Marjin Perdagangan Eceran | GW5: Biaya Pengangkutan | GX5: Total Marjin Perdagangan dan Biaya Pengangkutan | GY5: Total Pajak dikurang Subsidi atas Produk | GZ5: Output Domestik Harga Dasar | HA5: Total Penyediaan
B6: 1 | C6: Padi | D6: 21245629 | E6: - | F6: - | G6: - | H6: - | I6: - | J6: - | K6: - | L6: - | M6: - | N6: - | O6: - | P6: - | Q6: - | R6: - | S6: - | T6: - | U6: - | V6: - | W6: - | X6: - | Y6: - | Z6: - | AA6: - | AB6: - | AC6: 1341712 | AD6: 151784 | AE6: 411729 | AF6: 298488 | AG6: - | AH6: - | AI6: - | AJ6: 137340 | AK6: 244333 | AL6: - | AM6: - | AN6: - | AO6: - | AP6: - | AQ6: - | AR6: - | AS6: - | AT6: - | AU6: - | AV6: - | AW6: - | AX6: - | AY6: - | AZ6: - | BA6: - | BB6: - | BC6: - | BD6: - | BE6: - | BF6: - | BG6: - | BH6: - | BI6: - | BJ6: - | BK6: - | BL6: - | BM6: - | BN6: 246375356 | BO6: - | BP6: - | BQ6: - | BR6: - | BS6: - | BT6: - | BU6: - | BV6: 268 | BW6: 12157762 | BX6: 7066 | BY6: - | BZ6: - | CA6: - | CB6: - | CC6: - | CD6: - | CE6: - | CF6: - | CG6: - | CH6: - | CI6: - | CJ6: - | CK6: - | CL6: - | CM6: - | CN6: - | CO6: - | CP6: - | CQ6: - | CR6: - | CS6: - | CT6: - | CU6: - | CV6: - | CW6: - | CX6: - | CY6: - | CZ6: - | DA6: - | DB6: - | DC6: - | DD6: - | DE6: - | DF6: - | DG6: - | DH6: - | DI6: - | DJ6: - | DK6: - | DL6: - | DM6: - | DN6: - | DO6: - | DP6: - | DQ6: - | DR6: - | DS6: - | DT6: - | DU6: - | DV6: - | DW6: - | DX6: - | DY6: - | DZ6: - | EA6: - | EB6: - | EC6: - | ED6: - | EE6: - | EF6: - | EG6: - | EH6: - | EI6: - | EJ6: - | EK6: - | EL6: - | EM6: - | EN6: - | EO6: - | EP6: - | EQ6: - | ER6: - | ES6: - | ET6: - | EU6: - | EV6: - | EW6: - | EX6: - | EY6: - | EZ6: - | FA6: - | FB6: - | FC6: 2016087 | FD6: - | FE6: 199150 | FF6: - | FG6: - | FH6: - | FI6: - | FJ6: - | FK6: - | FL6: - | FM6: - | FN6: - | FO6: - | FP6: - | FQ6: - | FR6: - | FS6: - | FT6: - | FU6: - | FV6: - | FW6: - | FX6: 172297 | FY6: - | FZ6: - | GA6: - | GB6: 84812 | GC6: - | GD6: - | GE6: - | GF6: - | GG6: 284843813 | GH6: - | GI6: - | GJ6: - | GK6: - | GL6: 7607 | GM6: 5825 | GN6: - | GO6: 13432 | GP6: 284857245 | GQ6: 7749 | GR6: - | GS6: - | GT6: 7749 | GU6: - | GV6: - | GW6: - | GX6: - | GY6: - | GZ6: 284849496 | HA6: 284857245
B7: 2 | C7: Jagung | D7: - | E7: 3818066 | F7: - | G7: - | H7: - | I7: - | J7: - | K7: - | L7: - | M7: - | N7: - | O7: - | P7: - | Q7: - | R7: - | S7: - | T7: - | U7: - | V7: - | W7: - | X7: - | Y7: - | Z7: - | AA7: - | AB7: - | AC7: 491240 | AD7: 359363 | AE7: 1868479 | AF7: 51583 | AG7: - | AH7: - | AI7: - | AJ7: 447882 | AK7: 30033 | AL7: 10171 | AM7: - | AN7: - | AO7: - | AP7: - | AQ7: - | AR7: - | AS7: - | AT7: - | AU7: - | AV7: - | AW7: - | AX7: - | AY7: - | AZ7: - | BA7: - | BB7: - | BC7: - | BD7: - | BE7: - | BF7: - | BG7: - | BH7: - | BI7: 1733267 | BJ7: - | BK7: - | BL7: 4639432 | BM7: 113244 | BN7: - | BO7: - | BP7: 4466 | BQ7: - | BR7: - | BS7: 1594641 | BT7: - | BU7: 905244 | BV7: 8492975 | BW7: 27817233 | BX7: 83755 | BY7: 220170 | BZ7: 1275169 | CA7: 77776 | CB7: - | CC7: - | CD7: - | CE7: - | CF7: - | CG7: - | CH7: - | CI7: - | CJ7: - | CK7: - | CL7: - | CM7: - | CN7: - | CO7: - | CP7: - | CQ7: - | CR7: - | CS7: - | CT7: - | CU7: - | CV7: - | CW7: - | CX7: - | CY7: - | CZ7: - | DA7: - | DB7: - | DC7: - | DD7: - | DE7: 510 | DF7: - | DG7: - | DH7: - | DI7: - | DJ7: - | DK7: - | DL7: - | DM7: - | DN7: - | DO7: - | DP7: - | DQ7: - | DR7: - | DS7: - | DT7: - | DU7: - | DV7: - | DW7: - | DX7: - | DY7: - | DZ7: - | EA7: - | EB7: - | EC7: - | ED7: - | EE7: - | EF7: - | EG7: - | EH7: - | EI7: - | EJ7: - | EK7: - | EL7: - | EM7: - | EN7: - | EO7: - | EP7: - | EQ7: - | ER7: - | ES7: - | ET7: - | EU7: - | EV7: - | EW7: - | EX7: - | EY7: - | EZ7: - | FA7: - | FB7: - | FC7: - | FD7: - | FE7: - | FF7: - | FG7: - | FH7: - | FI7: - | FJ7: - | FK7: 256327 | FL7: 10686503 | FM7: - | FN7: - | FO7: - | FP7: - | FQ7: - | FR7: - | FS7: - | FT7: - | FU7: - | FV7: - | FW7: - | FX7: 152340 | FY7: 384 | FZ7: 5668 | GA7: 68 | GB7: 30700 | GC7: 306931 | GD7: 71937 | GE7: - | GF7: 98393 | GG7: 65643950 | GH7: 13875288 | GI7: - | GJ7: - | GK7: - | GL7: 2136474 | GM7: 211937 | GN7: - | GO7: 16223699 | GP7: 81867649 | GQ7: 2691076 | GR7: - | GS7: - | GT7: 2691076 | GU7: - | GV7: - | GW7: - | GX7: - | GY7: - | GZ7: 79176573 | HA7: 81867649
B8: 3 | C8: Ubi jalar | D8: - | E8: - | F8: 468534 | G8: - | H8: - | I8: - | J8: - | K8: - | L8: - | M8: - | N8: - | O8: - | P8: - | Q8: - | R8: - | S8: - | T8: - | U8: - | V8: - | W8: - | X8: - | Y8: - | Z8: - | AA8: - | AB8: - | AC8: 82536 | AD8: 44929 | AE8: 51317 | AF8: 6664 | AG8: - | AH8: - | AI8: - | AJ8: - | AK8: - | AL8: - | AM8: - | AN8: - | AO8: - | AP8: - | AQ8: - | AR8: - | AS8: - | AT8: - | AU8: - | AV8: - | AW8: - | AX8: - | AY8: - | AZ8: - | BA8: - | BB8: - | BC8: - | BD8: - | BE8: - | BF8: - | BG8: - | BH8: 6726 | BI8: - | BJ8: - | BK8: - | BL8: 383925 | BM8: - | BN8: - | BO8: - | BP8: 521 | BQ8: - | BR8: - | BS8: - | BT8: - | BU8: - | BV8: 1209103 | BW8: 36820 | BX8: 24 | BY8: - | BZ8: - | CA8: - | CB8: - | CC8: - | CD8: - | CE8: - | CF8: - | CG8: - | CH8: - | CI8: - | CJ8: - | CK8: - | CL8: - | CM8: - | CN8: - | CO8: - | CP8: - | CQ8: - | CR8: - | CS8: - | CT8: - | CU8: - | CV8: - | CW8: - | CX8: - | CY8: - | CZ8: - | DA8: - | DB8: - | DC8: - | DD8: - | DE8: 156 | DF8: - | DG8: - | DH8: - | DI8: - | DJ8: - | DK8: - | DL8: - | DM8: - | DN8: - | DO8: - | DP8: - | DQ8: - | DR8: - | DS8: - | DT8: - | DU8: - | DV8: - | DW8: - | DX8: - | DY8: - | DZ8: - | EA8: - | EB8: - | EC8: - | ED8: - | EE8: - | EF8: - | EG8: - | EH8: - | EI8: - | EJ8: - | EK8: - | EL8: - | EM8: - | EN8: - | EO8: - | EP8: - | EQ8: - | ER8: - | ES8: - | ET8: - | EU8: - | EV8: - | EW8: - | EX8: - | EY8: - | EZ8: - | FA8: - | FB8: - | FC8: - | FD8: - | FE8: - | FF8: - | FG8: - | FH8: - | FI8: - | FJ8: - | FK8: 47797 | FL8: 561366 | FM8: - | FN8: - | FO8: - | FP8: - | FQ8: - | FR8: - | FS8: - | FT8: - | FU8: - | FV8: - | FW8: - | FX8: 3556 | FY8: 212 | FZ8: 103766 | GA8: 27 | GB8: 3520 | GC8: 45938 | GD8: 193077 | GE8: - | GF8: 1258 | GG8: 3251772 | GH8: 5993774 | GI8: - | GJ8: - | GK8: - | GL8: -243255 | GM8: 132618 | GN8: - | GO8: 5883137 | GP8: 9134909 | GQ8: 1 | GR8: - | GS8: - | GT8: 1 | GU8: - | GV8: - | GW8: - | GX8: - | GY8: - | GZ8: 9134908 | HA8: 9134909
B9: 4 | C9: Ubi kayu | D9: - | E9: - | F9: - | G9: 3078120 | H9: - | I9: - | J9: - | K9: - | L9: - | M9: - | N9: - | O9: - | P9: - | Q9: - | R9: - | S9: - | T9: - | U9: - | V9: - | W9: - | X9: - | Y9: - | Z9: - | AA9: - | AB9: - | AC9: 341921 | AD9: 45238 | AE9: 264410 | AF9: 17152 | AG9: 252 | AH9: - | AI9: - | AJ9: 67671 | AK9: 355 | AL9: 146 | AM9: - | AN9: - | AO9: - | AP9: - | AQ9: - | AR9: - | AS9: - | AT9: - | AU9: - | AV9: - | AW9: - | AX9: - | AY9: - | AZ9: - | BA9: - | BB9: - | BC9: - | BD9: - | BE9: - | BF9: - | BG9: - | BH9: - | BI9: - | BJ9: - | BK9: - | BL9: 7955946 | BM9: 217613 | BN9: - | BO9: - | BP9: 88060 | BQ9: - | BR9: - | BS9: - | BT9: - | BU9: - | BV9: 14646320 | BW9: 1725987 | BX9: 2214 | BY9: - | BZ9: - | CA9: - | CB9: - | CC9: - | CD9: - | CE9: - | CF9: - | CG9: - | CH9: - | CI9: - | CJ9: - | CK9: - | CL9: - | CM9: - | CN9: - | CO9: - | CP9: - | CQ9: - | CR9: - | CS9: - | CT9: - | CU9: - | CV9: - | CW9: - | CX9: - | CY9: - | CZ9: - | DA9: - | DB9: - | DC9: - | DD9: - | DE9: 310 | DF9: - | DG9: - | DH9: - | DI9: - | DJ9: - | DK9: - | DL9: - | DM9: - | DN9: - | DO9: - | DP9: - | DQ9: - | DR9: - | DS9: - | DT9: - | DU9: - | DV9: - | DW9: - | DX9: - | DY9: - | DZ9: - | EA9: - | EB9: - | EC9: - | ED9: - | EE9: - | EF9: - | EG9: - | EH9: - | EI9: - | EJ9: - | EK9: - | EL9: - | EM9: - | EN9: - | EO9: - | EP9: - | EQ9: - | ER9: - | ES9: - | ET9: - | EU9: - | EV9: - | EW9: - | EX9: - | EY9: - | EZ9: - | FA9: - | FB9: - | FC9: - | FD9: - | FE9: - | FF9: - | FG9: - | FH9: - | FI9: - | FJ9: - | FK9: 174835 | FL9: 12568256 | FM9: - | FN9: - | FO9: - | FP9: - | FQ9: - | FR9: - | FS9: - | FT9: - | FU9: - | FV9: - | FW9: - | FX9: 1147 | FY9: 117 | FZ9: 41169 | GA9: 54 | GB9: 12909 | GC9: 36740 | GD9: 112020 | GE9: - | GF9: 893 | GG9: 41399855 | GH9: 12645484 | GI9: - | GJ9: - | GK9: - | GL9: -20157 | GM9: 114368 | GN9: - | GO9: 12739695 | GP9: 54139550 | GQ9: 8617 | GR9: - | GS9: - | GT9: 8617 | GU9: - | GV9: - | GW9: - | GX9: - | GY9: - | GZ9: 54130933 | HA9: 54139550
B10: 5 | C10: Umbi-umbian lainnya | D10: - | E10: - | F10: - | G10: - | H10: 130843 | I10: - | J10: - | K10: - | L10: - | M10: - | N10: - | O10: - | P10: - | Q10: - | R10: - | S10: - | T10: - | U10: - | V10: - | W10: - | X10: - | Y10: - | Z10: - | AA10: - | AB10: - | AC10: 144426 | AD10: 21287 | AE10: 76 | AF10: 212 | AG10: - | AH10: - | AI10: - | AJ10: - | AK10: - | AL10: - | AM10: - | AN10: - | AO10: - | AP10: - | AQ10: - | AR10: - | AS10: - | AT10: - | AU10: - | AV10: - | AW10: - | AX10: - | AY10: - | AZ10: - | BA10: - | BB10: - | BC10: - | BD10: - | BE10: - | BF10: - | BG10: - | BH10: - | BI10: - | BJ10: - | BK10: - | BL10: 29330 | BM10: - | BN10: - | BO10: - | BP10: - | BQ10: - | BR10: 122 | BS10: - | BT10: - | BU10: - | BV10: 806157 | BW10: 68503 | BX10: 32 | BY10: 385 | BZ10: - | CA10: - | CB10: - | CC10: - | CD10: - | CE10: - | CF10: - | CG10: - | CH10: - | CI10: - | CJ10: - | CK10: - | CL10: - | CM10: - | CN10: - | CO10: - | CP10: - | CQ10: - | CR10: - | CS10: - | CT10: - | CU10: - | CV10: - | CW10: - | CX10: - | CY10: - | CZ10: - | DA10: - | DB10: - | DC10: - | DD10: - | DE10: 83 | DF10: - | DG10: - | DH10: - | DI10: - | DJ10: - | DK10: - | DL10: - | DM10: - | DN10: - | DO10: - | DP10: - | DQ10: - | DR10: - | DS10: - | DT10: - | DU10: - | DV10: - | DW10: - | DX10: - | DY10: - | DZ10: - | EA10: - | EB10: - | EC10: - | ED10: - | EE10: - | EF10: - | EG10: - | EH10: - | EI10: - | EJ10: - | EK10: - | EL10: - | EM10: - | EN10: - | EO10: - | EP10: - | EQ10: - | ER10: - | ES10: - | ET10: - | EU10: - | EV10: - | EW10: - | EX10: - | EY10: - | EZ10: - | FA10: - | FB10: - | FC10: - | FD10: - | FE10: - | FF10: - | FG10: - | FH10: - | FI10: - | FJ10: - | FK10: 69016 | FL10: 209019 | FM10: - | FN10: - | FO10: - | FP10: - | FQ10: - | FR10: - | FS10: - | FT10: - | FU10: - | FV10: - | FW10: - | FX10: 73295 | FY10: 3803 | FZ10: 233727 | GA10: 5510 | GB10: 2922 | GC10: 17691 | GD10: 50278 | GE10: - | GF10: 11076 | GG10: 1877793 | GH10: 1172358 | GI10: - | GJ10: - | GK10: - | GL10: 14 | GM10: 315024 | GN10: - | GO10: 1487396 | GP10: 3365189 | GQ10: 20483 | GR10: - | GS10: - | GT10: 20483 | GU10: - | GV10: - | GW10: - | GX10: - | GY10: - | GZ10: 3344706 | HA10: 3365189
B11: 6 | C11: Kacang tanah | D11: - | E11: - | F11: - | G11: - | H11: - | I11: 273532 | J11: - | K11: - | L11: - | M11: - | N11: - | O11: - | P11: - | Q11: - | R11: - | S11: - | T11: - | U11: - | V11: - | W11: - | X11: - | Y11: - | Z11: - | AA11: - | AB11: - | AC11: 31884 | AD11: 914 | AE11: 14353 | AF11: 2271 | AG11: - | AH11: - | AI11: - | AJ11: - | AK11: - | AL11: - | AM11: - | AN11: - | AO11: - | AP11: - | AQ11: - | AR11: - | AS11: - | AT11: - | AU11: - | AV11: - | AW11: - | AX11: - | AY11: - | AZ11: - | BA11: - | BB11: - | BC11: - | BD11: - | BE11: - | BF11: - | BG11: - | BH11: 443328 | BI11: 16644 | BJ11: - | BK11: - | BL11: 503477 | BM11: - | BN11: - | BO11: - | BP11: - | BQ11: - | BR11: - | BS11: 342 | BT11: - | BU11: - | BV11: 2410591 | BW11: 399185 | BX11: - | BY11: 25995 | BZ11: - | CA11: - | CB11: - | CC11: - | CD11: - | CE11: - | CF11: - | CG11: - | CH11: - | CI11: - | CJ11: - | CK11: - | CL11: - | CM11: - | CN11: - | CO11: - | CP11: - | CQ11: - | CR11: - | CS11: - | CT11: - | CU11: - | CV11: - | CW11: - | CX11: - | CY11: - | CZ11: - | DA11: - | DB11: - | DC11: - | DD11: 779 | DE11: 48 | DF11: - | DG11: - | DH11: - | DI11: - | DJ11: - | DK11: - | DL11: - | DM11: - | DN11: - | DO11: - | DP11: - | DQ11: - | DR11: - | DS11: - | DT11: - | DU11: - | DV11: - | DW11: - | DX11: - | DY11: - | DZ11: - | EA11: - | EB11: - | EC11: - | ED11: - | EE11: - | EF11: - | EG11: - | EH11: - | EI11: - | EJ11: - | EK11: - | EL11: - | EM11: - | EN11: - | EO11: - | EP11: - | EQ11: - | ER11: - | ES11: - | ET11: - | EU11: - | EV11: - | EW11: - | EX11: - | EY11: - | EZ11: - | FA11: - | FB11: - | FC11: - | FD11: - | FE11: - | FF11: - | FG11: - | FH11: - | FI11: - | FJ11: - | FK11: 17964 | FL11: 394998 | FM11: - | FN11: - | FO11: - | FP11: - | FQ11: - | FR11: - | FS11: - | FT11: - | FU11: - | FV11: - | FW11: - | FX11: 36810 | FY11: 2275 | FZ11: 4687 | GA11: 3539 | GB11: 8704 | GC11: 19012 | GD11: 23843 | GE11: - | GF11: 30646 | GG11: 4665821 | GH11: 2535612 | GI11: - | GJ11: - | GK11: - | GL11: 52310 | GM11: 61767 | GN11: - | GO11: 2649689 | GP11: 7315510 | GQ11: 114879 | GR11: - | GS11: - | GT11: 114879 | GU11: - | GV11: - | GW11: - | GX11: - | GY11: - | GZ11: 7200631 | HA11: 7315510
B12: 7 | C12: Kedelai | D12: - | E12: - | F12: - | G12: - | H12: - | I12: - | J12: 195011 | K12: - | L12: - | M12: - | N12: - | O12: - | P12: - | Q12: - | R12: - | S12: - | T12: - | U12: - | V12: - | W12: - | X12: - | Y12: - | Z12: - | AA12: - | AB12: - | AC12: 15432 | AD12: 99 | AE12: 1039 | AF12: 988 | AG12: - | AH12: - | AI12: - | AJ12: - | AK12: - | AL12: - | AM12: - | AN12: - | AO12: - | AP12: - | AQ12: - | AR12: - | AS12: - | AT12: - | AU12: - | AV12: - | AW12: - | AX12: - | AY12: - | AZ12: - | BA12: - | BB12: - | BC12: - | BD12: - | BE12: - | BF12: - | BG12: - | BH12: 1464129 | BI12: 5580 | BJ12: - | BK12: - | BL12: 335003 | BM12: - | BN12: - | BO12: - | BP12: - | BQ12: - | BR12: - | BS12: 51 | BT12: - | BU12: 16229170 | BV12: 15000 | BW12: 3916 | BX12: 1602 | BY12: 56875 | BZ12: - | CA12: - | CB12: - | CC12: - | CD12: - | CE12: - | CF12: - | CG12: - | CH12: - | CI12: - | CJ12: - | CK12: - | CL12: - | CM12: - | CN12: - | CO12: - | CP12: - | CQ12: - | CR12: - | CS12: - | CT12: - | CU12: - | CV12: - | CW12: - | CX12: - | CY12: - | CZ12: - | DA12: - | DB12: - | DC12: - | DD12: 101 | DE12: 25 | DF12: - | DG12: - | DH12: - | DI12: - | DJ12: - | DK12: - | DL12: - | DM12: - | DN12: - | DO12: - | DP12: - | DQ12: - | DR12: - | DS12: - | DT12: - | DU12: - | DV12: - | DW12: - | DX12: - | DY12: - | DZ12: - | EA12: - | EB12: - | EC12: - | ED12: - | EE12: - | EF12: - | EG12: - | EH12: - | EI12: - | EJ12: - | EK12: - | EL12: - | EM12: - | EN12: - | EO12: - | EP12: - | EQ12: - | ER12: - | ES12: - | ET12: - | EU12: - | EV12: - | EW12: - | EX12: - | EY12: - | EZ12: - | FA12: - | FB12: - | FC12: - | FD12: - | FE12: - | FF12: - | FG12: - | FH12: - | FI12: - | FJ12: - | FK12: 49 | FL12: 7452 | FM12: - | FN12: - | FO12: - | FP12: - | FQ12: - | FR12: - | FS12: - | FT12: - | FU12: - | FV12: - | FW12: - | FX12: 35523 | FY12: 100 | FZ12: 1963 | GA12: 89 | GB12: 3742 | GC12: 4156 | GD12: 3778 | GE12: - | GF12: 17573 | GG12: 18398446 | GH12: 798232 | GI12: - | GJ12: - | GK12: - | GL12: 371502 | GM12: 7135 | GN12: - | GO12: 1176869 | GP12: 19575315 | GQ12: 15291539 | GR12: - | GS12: - | GT12: 15291539 | GU12: - | GV12: - | GW12: - | GX12: - | GY12: - | GZ12: 4283776 | HA12: 19575315
B13: 8 | C13: Kacang-kacangan Lainnya | D13: - | E13: - | F13: - | G13: - | H13: - | I13: - | J13: - | K13: 525023 | L13: - | M13: - | N13: - | O13: - | P13: - | Q13: - | R13: - | S13: - | T13: - | U13: - | V13: - | W13: - | X13: - | Y13: - | Z13: - | AA13: - | AB13: - | AC13: 9389 | AD13: 280 | AE13: 5610 | AF13: 1457 | AG13: - | AH13: - | AI13: - | AJ13: - | AK13: - | AL13: - | AM13: - | AN13: - | AO13: - | AP13: - | AQ13: - | AR13: - | AS13: - | AT13: - | AU13: - | AV13: - | AW13: - | AX13: - | AY13: - | AZ13: - | BA13: - | BB13: - | BC13: - | BD13: - | BE13: - | BF13: - | BG13: - | BH13: - | BI13: 57 | BJ13: - | BK13: - | BL13: 9331 | BM13: - | BN13: - | BO13: 48401 | BP13: - | BQ13: - | BR13: - | BS13: 78 | BT13: - | BU13: 57879 | BV13: 215944 | BW13: 37946 | BX13: 23 | BY13: 182523 | BZ13: - | CA13: - | CB13: - | CC13: - | CD13: - | CE13: - | CF13: - | CG13: - | CH13: - | CI13: - | CJ13: - | CK13: - | CL13: - | CM13: - | CN13: - | CO13: - | CP13: - | CQ13: - | CR13: - | CS13: - | CT13: - | CU13: - | CV13: - | CW13: - | CX13: - | CY13: - | CZ13: - | DA13: - | DB13: - | DC13: - | DD13: 595 | DE13: 9 | DF13: - | DG13: - | DH13: - | DI13: - | DJ13: - | DK13: - | DL13: - | DM13: - | DN13: - | DO13: - | DP13: - | DQ13: - | DR13: - | DS13: - | DT13: - | DU13: - | DV13: - | DW13: - | DX13: - | DY13: - | DZ13: - | EA13: - | EB13: - | EC13: - | ED13: - | EE13: - | EF13: - | EG13: - | EH13: - | EI13: - | EJ13: - | EK13: - | EL13: - | EM13: - | EN13: - | EO13: - | EP13: - | EQ13: - | ER13: - | ES13: - | ET13: - | EU13: - | EV13: - | EW13: - | EX13: - | EY13: - | EZ13: - | FA13: - | FB13: - | FC13: - | FD13: - | FE13: - | FF13: - | FG13: - | FH13: - | FI13: - | FJ13: - | FK13: 3345 | FL13: 70896 | FM13: - | FN13: - | FO13: - | FP13: - | FQ13: - | FR13: - | FS13: - | FT13: - | FU13: - | FV13: - | FW13: - | FX13: - | FY13: 1196 | FZ13: 1388 | GA13: 356 | GB13: 14103 | GC13: 28298 | GD13: 14170 | GE13: - | GF13: 67025 | GG13: 1295322 | GH13: 11145361 | GI13: - | GJ13: - | GK13: - | GL13: 9 | GM13: 32616 | GN13: - | GO13: 11177986 | GP13: 12473308 | GQ13: - | GR13: - | GS13: - | GT13: - | GU13: - | GV13: - | GW13: - | GX13: - | GY13: - | GZ13: 12473308 | HA13: 12473308
B14: 9 | C14: Padi-padian dan Bahan Makanan Lainnya | D14: - | E14: - | F14: - | G14: - | H14: - | I14: - | J14: - | K14: - | L14: 28143 | M14: - | N14: - | O14: - | P14: - | Q14: - | R14: - | S14: - | T14: - | U14: - | V14: - | W14: - | X14: - | Y14: - | Z14: - | AA14: - | AB14: - | AC14: - | AD14: - | AE14: 4696 | AF14: 153673 | AG14: - | AH14: - | AI14: - | AJ14: - | AK14: - | AL14: - | AM14: - | AN14: - | AO14: - | AP14: - | AQ14: - | AR14: - | AS14: - | AT14: - | AU14: - | AV14: - | AW14: - | AX14: - | AY14: - | AZ14: - | BA14: - | BB14: - | BC14: - | BD14: - | BE14: - | BF14: - | BG14: - | BH14: - | BI14: 6837796 | BJ14: - | BK14: - | BL14: 2580462 | BM14: 25408585 | BN14: - | BO14: - | BP14: 82233 | BQ14: 18988 | BR14: - | BS14: - | BT14: - | BU14: - | BV14: 142483 | BW14: 13588 | BX14: 2613194 | BY14: 3055 | BZ14: - | CA14: - | CB14: - | CC14: - | CD14: - | CE14: - | CF14: - | CG14: - | CH14: - | CI14: - | CJ14: - | CK14: - | CL14: - | CM14: - | CN14: - | CO14: - | CP14: - | CQ14: - | CR14: - | CS14: - | CT14: - | CU14: - | CV14: - | CW14: - | CX14: - | CY14: - | CZ14: - | DA14: - | DB14: - | DC14: 15239 | DD14: 24251 | DE14: - | DF14: - | DG14: - | DH14: - | DI14: - | DJ14: - | DK14: - | DL14: - | DM14: - | DN14: - | DO14: - | DP14: - | DQ14: - | DR14: - | DS14: - | DT14: - | DU14: - | DV14: - | DW14: - | DX14: - | DY14: - | DZ14: - | EA14: - | EB14: - | EC14: - | ED14: - | EE14: - | EF14: - | EG14: - | EH14: - | EI14: - | EJ14: - | EK14: - | EL14: - | EM14: - | EN14: - | EO14: - | EP14: - | EQ14: - | ER14: - | ES14: - | ET14: - | EU14: - | EV14: - | EW14: - | EX14: - | EY14: - | EZ14: - | FA14: - | FB14: - | FC14: - | FD14: - | FE14: - | FF14: - | FG14: - | FH14: - | FI14: - | FJ14: - | FK14: 401824 | FL14: 1769850 | FM14: - | FN14: - | FO14: - | FP14: - | FQ14: - | FR14: - | FS14: - | FT14: - | FU14: - | FV14: - | FW14: - | FX14: - | FY14: 22611 | FZ14: 25722 | GA14: 42581 | GB14: 110868 | GC14: 418389 | GD14: 23802 | GE14: - | GF14: 511147 | GG14: 41253180 | GH14: 170520 | GI14: - | GJ14: - | GK14: - | GL14: -3268 | GM14: 40444 | GN14: - | GO14: 207696 | GP14: 41460876 | GQ14: 41057663 | GR14: - | GS14: - | GT14: 41057663 | GU14: - | GV14: - | GW14: - | GX14: - | GY14: - | GZ14: 403213 | HA14: 41460876
B15: 10 | C15: Sayur-sayuran | D15: - | E15: - | F15: - | G15: - | H15: - | I15: - | J15: - | K15: - | L15: - | M15: 7102609 | N15: - | O15: - | P15: - | Q15: - | R15: - | S15: - | T15: - | U15: - | V15: - | W15: - | X15: - | Y15: - | Z15: - | AA15: - | AB15: - | AC15: 235192 | AD15: 5 | AE15: 489 | AF15: 140060 | AG15: - | AH15: - | AI15: - | AJ15: - | AK15: - | AL15: - | AM15: - | AN15: - | AO15: - | AP15: - | AQ15: - | AR15: - | AS15: - | AT15: - | AU15: - | AV15: - | AW15: - | AX15: - | AY15: - | AZ15: - | BA15: - | BB15: - | BC15: - | BD15: - | BE15: - | BF15: 6628 | BG15: 9542 | BH15: 1728929 | BI15: - | BJ15: - | BK15: - | BL15: 11442 | BM15: - | BN15: - | BO15: - | BP15: - | BQ15: 7502 | BR15: 4449686 | BS15: - | BT15: - | BU15: 76952 | BV15: 14005739 | BW15: 75241 | BX15: 11194 | BY15: 12521 | BZ15: - | CA15: - | CB15: - | CC15: - | CD15: - | CE15: - | CF15: - | CG15: - | CH15: - | CI15: - | CJ15: - | CK15: - | CL15: - | CM15: - | CN15: - | CO15: - | CP15: - | CQ15: - | CR15: - | CS15: - | CT15: - | CU15: - | CV15: - | CW15: - | CX15: - | CY15: - | CZ15: - | DA15: - | DB15: - | DC15: - | DD15: 191555 | DE15: 59850 | DF15: - | DG15: - | DH15: - | DI15: - | DJ15: - | DK15: - | DL15: - | DM15: - | DN15: - | DO15: - | DP15: - | DQ15: - | DR15: - | DS15: - | DT15: - | DU15: - | DV15: - | DW15: - | DX15: - | DY15: - | DZ15: - | EA15: - | EB15: - | EC15: - | ED15: - | EE15: - | EF15: - | EG15: - | EH15: - | EI15: - | EJ15: - | EK15: - | EL15: - | EM15: - | EN15: - | EO15: - | EP15: - | EQ15: - | ER15: - | ES15: - | ET15: - | EU15: - | EV15: - | EW15: - | EX15: - | EY15: - | EZ15: - | FA15: - | FB15: - | FC15: - | FD15: - | FE15: - | FF15: - | FG15: - | FH15: - | FI15: - | FJ15: - | FK15: 3071318 | FL15: 21709124 | FM15: - | FN15: - | FO15: - | FP15: - | FQ15: - | FR15: - | FS15: - | FT15: - | FU15: - | FV15: - | FW15: - | FX15: 632470 | FY15: 21090 | FZ15: 155579 | GA15: 33073 | GB15: 70862 | GC15: 989755 | GD15: 965987 | GE15: - | GF15: 119068 | GG15: 55893462 | GH15: 140792281 | GI15: - | GJ15: - | GK15: 794955 | GL15: 169911 | GM15: 1257072 | GN15: - | GO15: 143014219 | GP15: 198907681 | GQ15: 13291834 | GR15: - | GS15: - | GT15: 13291834 | GU15: - | GV15: - | GW15: - | GX15: - | GY15: - | GZ15: 185615847 | HA15: 198907681
B16: 11 | C16: Tanaman Hias dan Holtikultura Lainnya | D16: - | E16: - | F16: - | G16: - | H16: - | I16: - | J16: - | K16: - | L16: - | M16: - | N16: 212648 | O16: - | P16: - | Q16: - | R16: - | S16: - | T16: - | U16: - | V16: - | W16: - | X16: - | Y16: - | Z16: - | AA16: - | AB16: - | AC16: 777298 | AD16: 35884 | AE16: 217899 | AF16: 42995 | AG16: - | AH16: - | AI16: - | AJ16: 197031 | AK16: - | AL16: - | AM16: - | AN16: - | AO16: - | AP16: - | AQ16: - | AR16: - | AS16: - | AT16: - | AU16: - | AV16: - | AW16: - | AX16: - | AY16: - | AZ16: - | BA16: - | BB16: - | BC16: - | BD16: - | BE16: - | BF16: - | BG16: - | BH16: - | BI16: - | BJ16: - | BK16: - | BL16: - | BM16: - | BN16: - | BO16: - | BP16: - | BQ16: - | BR16: - | BS16: - | BT16: 941209 | BU16: - | BV16: - | BW16: 111453 | BX16: - | BY16: 1593 | BZ16: 130 | CA16: - | CB16: - | CC16: - | CD16: - | CE16: - | CF16: - | CG16: - | CH16: - | CI16: - | CJ16: - | CK16: - | CL16: - | CM16: - | CN16: - | CO16: - | CP16: - | CQ16: - | CR16: - | CS16: - | CT16: - | CU16: - | CV16: - | CW16: - | CX16: - | CY16: - | CZ16: - | DA16: - | DB16: - | DC16: 3145 | DD16: 325912 | DE16: 33139 | DF16: - | DG16: - | DH16: - | DI16: - | DJ16: - | DK16: - | DL16: - | DM16: - | DN16: - | DO16: - | DP16: - | DQ16: - | DR16: - | DS16: - | DT16: - | DU16: - | DV16: - | DW16: - | DX16: - | DY16: - | DZ16: - | EA16: - | EB16: - | EC16: - | ED16: - | EE16: - | EF16: - | EG16: - | EH16: - | EI16: - | EJ16: - | EK16: - | EL16: - | EM16: - | EN16: - | EO16: - | EP16: 394 | EQ16: - | ER16: - | ES16: - | ET16: - | EU16: 3560 | EV16: 665936 | EW16: 185322 | EX16: - | EY16: 39066 | EZ16: 109687 | FA16: - | FB16: - | FC16: - | FD16: - | FE16: - | FF16: - | FG16: - | FH16: - | FI16: - | FJ16: - | FK16: - | FL16: - | FM16: - | FN16: - | FO16: - | FP16: - | FQ16: - | FR16: - | FS16: - | FT16: - | FU16: - | FV16: - | FW16: - | FX16: 121824 | FY16: 1382 | FZ16: 862 | GA16: 203 | GB16: 17142 | GC16: 6392 | GD16: 626389 | GE16: - | GF16: 21655 | GG16: 4700150 | GH16: 996775 | GI16: - | GJ16: - | GK16: 124520 | GL16: 14253 | GM16: 427869 | GN16: - | GO16: 1563417 | GP16: 6263567 | GQ16: 267985 | GR16: - | GS16: - | GT16: 267985 | GU16: - | GV16: - | GW16: - | GX16: - | GY16: - | GZ16: 5995582 | HA16: 6263567
B17: 12 | C17: Tebu | D17: - | E17: - | F17: - | G17: - | H17: - | I17: - | J17: - | K17: - | L17: - | M17: - | N17: - | O17: 1683110 | P17: - | Q17: - | R17: - | S17: - | T17: - | U17: - | V17: - | W17: - | X17: - | Y17: - | Z17: - | AA17: - | AB17: - | AC17: 656480 | AD17: 47375 | AE17: 40 | AF17: - | AG17: - | AH17: - | AI17: - | AJ17: - | AK17: - | AL17: - | AM17: - | AN17: - | AO17: - | AP17: - | AQ17: - | AR17: - | AS17: - | AT17: - | AU17: - | AV17: - | AW17: - | AX17: - | AY17: - | AZ17: - | BA17: - | BB17: - | BC17: - | BD17: - | BE17: - | BF17: - | BG17: - | BH17: - | BI17: - | BJ17: - | BK17: 3286 | BL17: - | BM17: - | BN17: - | BO17: - | BP17: 17584855 | BQ17: - | BR17: - | BS17: - | BT17: 9572 | BU17: - | BV17: 311 | BW17: - | BX17: 31 | BY17: 19777 | BZ17: - | CA17: - | CB17: - | CC17: - | CD17: - | CE17: - | CF17: - | CG17: - | CH17: - | CI17: - | CJ17: - | CK17: - | CL17: - | CM17: - | CN17: - | CO17: - | CP17: - | CQ17: - | CR17: - | CS17: - | CT17: - | CU17: - | CV17: - | CW17: - | CX17: - | CY17: - | CZ17: - | DA17: - | DB17: - | DC17: - | DD17: 111 | DE17: 8374 | DF17: - | DG17: - | DH17: - | DI17: - | DJ17: - | DK17: - | DL17: - | DM17: - | DN17: - | DO17: - | DP17: - | DQ17: - | DR17: - | DS17: - | DT17: - | DU17: - | DV17: - | DW17: - | DX17: - | DY17: - | DZ17: - | EA17: - | EB17: - | EC17: - | ED17: - | EE17: - | EF17: - | EG17: - | EH17: - | EI17: - | EJ17: - | EK17: - | EL17: - | EM17: - | EN17: - | EO17: - | EP17: - | EQ17: - | ER17: - | ES17: - | ET17: - | EU17: - | EV17: - | EW17: - | EX17: - | EY17: - | EZ17: - | FA17: - | FB17: - | FC17: - | FD17: - | FE17: - | FF17: - | FG17: - | FH17: - | FI17: - | FJ17: - | FK17: - | FL17: 81726 | FM17: - | FN17: - | FO17: - | FP17: - | FQ17: - | FR17: - | FS17: - | FT17: - | FU17: - | FV17: - | FW17: - | FX17: 66240 | FY17: - | FZ17: - | GA17: - | GB17: 29 | GC17: - | GD17: - | GE17: - | GF17: - | GG17: 20161317 | GH17: - | GI17: - | GJ17: - | GK17: - | GL17: 330141 | GM17: 346 | GN17: - | GO17: 330487 | GP17: 20491804 | GQ17: - | GR17: - | GS17: - | GT17: - | GU17: - | GV17: - | GW17: - | GX17: - | GY17: - | GZ17: 20491804 | HA17: 20491804
B18: 13 | C18: Tembakau | D18: - | E18: - | F18: - | G18: - | H18: - | I18: - | J18: - | K18: - | L18: - | M18: - | N18: - | O18: - | P18: 502662 | Q18: - | R18: - | S18: - | T18: - | U18: - | V18: - | W18: - | X18: - | Y18: - | Z18: - | AA18: - | AB18: - | AC18: - | AD18: - | AE18: - | AF18: - | AG18: - | AH18: - | AI18: - | AJ18: - | AK18: - | AL18: - | AM18: - | AN18: - | AO18: - | AP18: - | AQ18: - | AR18: - | AS18: - | AT18: - | AU18: - | AV18: - | AW18: - | AX18: - | AY18: - | AZ18: - | BA18: - | BB18: - | BC18: - | BD18: - | BE18: - | BF18: - | BG18: - | BH18: - | BI18: - | BJ18: - | BK18: - | BL18: - | BM18: - | BN18: - | BO18: - | BP18: - | BQ18: - | BR18: - | BS18: - | BT18: - | BU18: - | BV18: - | BW18: - | BX18: - | BY18: - | BZ18: 20290710 | CA18: 1862019 | CB18: - | CC18: - | CD18: - | CE18: - | CF18: - | CG18: - | CH18: - | CI18: - | CJ18: - | CK18: - | CL18: - | CM18: - | CN18: - | CO18: - | CP18: - | CQ18: - | CR18: - | CS18: - | CT18: - | CU18: - | CV18: - | CW18: - | CX18: - | CY18: - | CZ18: - | DA18: - | DB18: - | DC18: - | DD18: 27 | DE18: 1764 | DF18: - | DG18: - | DH18: - | DI18: - | DJ18: - | DK18: - | DL18: - | DM18: - | DN18: - | DO18: - | DP18: - | DQ18: - | DR18: - | DS18: - | DT18: - | DU18: - | DV18: - | DW18: - | DX18: - | DY18: - | DZ18: - | EA18: - | EB18: - | EC18: - | ED18: - | EE18: - | EF18: - | EG18: - | EH18: - | EI18: - | EJ18: - | EK18: - | EL18: - | EM18: - | EN18: - | EO18: - | EP18: - | EQ18: - | ER18: - | ES18: - | ET18: - | EU18: - | EV18: - | EW18: - | EX18: - | EY18: - | EZ18: - | FA18: - | FB18: - | FC18: - | FD18: - | FE18: - | FF18: - | FG18: - | FH18: - | FI18: - | FJ18: - | FK18: - | FL18: - | FM18: - | FN18: - | FO18: - | FP18: - | FQ18: - | FR18: - | FS18: - | FT18: - | FU18: - | FV18: - | FW18: - | FX18: 244 | FY18: - | FZ18: - | GA18: - | GB18: - | GC18: - | GD18: - | GE18: - | GF18: - | GG18: 22657426 | GH18: - | GI18: - | GJ18: - | GK18: - | GL18: -165298 | GM18: 983105 | GN18: - | GO18: 817807 | GP18: 23475233 | GQ18: 1146398 | GR18: - | GS18: - | GT18: 1146398 | GU18: - | GV18: - | GW18: - | GX18: - | GY18: - | GZ18: 22328835 | HA18: 23475233
B19: 14 | C19: Tanaman serat | D19: - | E19: - | F19: - | G19: - | H19: - | I19: - | J19: - | K19: - | L19: - | M19: - | N19: - | O19: - | P19: - | Q19: 6621 | R19: - | S19: - | T19: - | U19: - | V19: - | W19: - | X19: - | Y19: - | Z19: - | AA19: - | AB19: - | AC19: - | AD19: - | AE19: - | AF19: - | AG19: - | AH19: - | AI19: - | AJ19: - | AK19: - | AL19: - | AM19: - | AN19: - | AO19: - | AP19: - | AQ19: - | AR19: - | AS19: - | AT19: - | AU19: - | AV19: - | AW19: - | AX19: - | AY19: - | AZ19: - | BA19: - | BB19: - | BC19: - | BD19: - | BE19: - | BF19: - | BG19: - | BH19: - | BI19: - | BJ19: - | BK19: - | BL19: - | BM19: - | BN19: - | BO19: - | BP19: - | BQ19: - | BR19: - | BS19: - | BT19: 613 | BU19: - | BV19: - | BW19: - | BX19: - | BY19: - | BZ19: - | CA19: - | CB19: 10446348 | CC19: 466190 | CD19: 876926 | CE19: 123861 | CF19: 102334 | CG19: 44243 | CH19: 1275 | CI19: 865 | CJ19: 5217 | CK19: - | CL19: 419678 | CM19: 58593 | CN19: - | CO19: - | CP19: - | CQ19: - | CR19: - | CS19: - | CT19: - | CU19: - | CV19: - | CW19: 6647 | CX19: - | CY19: - | CZ19: - | DA19: - | DB19: - | DC19: - | DD19: 30953 | DE19: 7035 | DF19: - | DG19: - | DH19: - | DI19: - | DJ19: - | DK19: - | DL19: - | DM19: - | DN19: - | DO19: - | DP19: - | DQ19: - | DR19: - | DS19: - | DT19: - | DU19: - | DV19: - | DW19: - | DX19: - | DY19: - | DZ19: - | EA19: - | EB19: - | EC19: - | ED19: - | EE19: - | EF19: - | EG19: - | EH19: - | EI19: - | EJ19: - | EK19: - | EL19: - | EM19: - | EN19: - | EO19: - | EP19: - | EQ19: - | ER19: - | ES19: - | ET19: - | EU19: - | EV19: - | EW19: - | EX19: - | EY19: - | EZ19: - | FA19: - | FB19: - | FC19: - | FD19: - | FE19: - | FF19: - | FG19: - | FH19: - | FI19: - | FJ19: - | FK19: - | FL19: - | FM19: - | FN19: - | FO19: - | FP19: - | FQ19: - | FR19: - | FS19: - | FT19: - | FU19: - | FV19: - | FW19: - | FX19: 106 | FY19: - | FZ19: - | GA19: - | GB19: - | GC19: - | GD19: - | GE19: - | GF19: - | GG19: 12597505 | GH19: - | GI19: - | GJ19: - | GK19: - | GL19: -182402 | GM19: 40669 | GN19: - | GO19: -141733 | GP19: 12455772 | GQ19: 11888095 | GR19: - | GS19: - | GT19: 11888095 | GU19: - | GV19: - | GW19: - | GX19: - | GY19: - | GZ19: 567677 | HA19: 12455772
B20: 15 | C20: Hasil Perkebunan Lainnya | D20: - | E20: - | F20: - | G20: - | H20: - | I20: - | J20: - | K20: - | L20: - | M20: - | N20: - | O20: - | P20: - | Q20: - | R20: 2203456 | S20: - | T20: - | U20: - | V20: - | W20: - | X20: - | Y20: - | Z20: - | AA20: - | AB20: - | AC20: - | AD20: - | AE20: - | AF20: - | AG20: - | AH20: - | AI20: - | AJ20: - | AK20: - | AL20: - | AM20: - | AN20: - | AO20: - | AP20: - | AQ20: - | AR20: - | AS20: - | AT20: - | AU20: - | AV20: - | AW20: - | AX20: - | AY20: - | AZ20: - | BA20: - | BB20: - | BC20: - | BD20: 6155 | BE20: - | BF20: - | BG20: 1524 | BH20: 60132 | BI20: 882391 | BJ20: - | BK20: 1148 | BL20: 1004 | BM20: - | BN20: - | BO20: - | BP20: - | BQ20: 8526 | BR20: 2465 | BS20: 1200 | BT20: 13954 | BU20: 62322 | BV20: 13373828 | BW20: - | BX20: 3 | BY20: 86445 | BZ20: 516 | CA20: - | CB20: - | CC20: - | CD20: - | CE20: - | CF20: - | CG20: - | CH20: - | CI20: - | CJ20: - | CK20: - | CL20: - | CM20: - | CN20: - | CO20: - | CP20: - | CQ20: - | CR20: - | CS20: - | CT20: - | CU20: - | CV20: - | CW20: - | CX20: - | CY20: - | CZ20: - | DA20: 60230 | DB20: - | DC20: 36272 | DD20: 786366 | DE20: 483239 | DF20: - | DG20: - | DH20: - | DI20: - | DJ20: - | DK20: - | DL20: - | DM20: - | DN20: - | DO20: - | DP20: - | DQ20: - | DR20: - | DS20: - | DT20: - | DU20: - | DV20: - | DW20: - | DX20: - | DY20: - | DZ20: - | EA20: - | EB20: - | EC20: - | ED20: - | EE20: - | EF20: - | EG20: - | EH20: - | EI20: - | EJ20: 16 | EK20: - | EL20: - | EM20: - | EN20: - | EO20: - | EP20: - | EQ20: - | ER20: - | ES20: - | ET20: - | EU20: - | EV20: - | EW20: - | EX20: - | EY20: - | EZ20: - | FA20: - | FB20: - | FC20: - | FD20: - | FE20: - | FF20: - | FG20: - | FH20: - | FI20: - | FJ20: - | FK20: 251977 | FL20: 2120803 | FM20: - | FN20: - | FO20: - | FP20: - | FQ20: - | FR20: - | FS20: - | FT20: - | FU20: - | FV20: - | FW20: - | FX20: 15846 | FY20: 108 | FZ20: 5491 | GA20: - | GB20: 1 | GC20: 437 | GD20: 8450 | GE20: - | GF20: - | GG20: 20474305 | GH20: 1217970 | GI20: - | GJ20: - | GK20: 20268278 | GL20: 4723074 | GM20: 5043075 | GN20: - | GO20: 31252397 | GP20: 51726702 | GQ20: 669921 | GR20: - | GS20: - | GT20: 669921 | GU20: - | GV20: - | GW20: - | GX20: - | GY20: - | GZ20: 51056781 | HA20: 51726702
B21: 16 | C21: Buah-buahan | D21: - | E21: - | F21: - | G21: - | H21: - | I21: - | J21: - | K21: - | L21: - | M21: - | N21: - | O21: - | P21: - | Q21: - | R21: - | S21: 6334855 | T21: - | U21: - | V21: - | W21: - | X21: - | Y21: - | Z21: - | AA21: - | AB21: - | AC21: 291915 | AD21: - | AE21: 679 | AF21: 59991 | AG21: - | AH21: - | AI21: - | AJ21: 3693 | AK21: - | AL21: - | AM21: - | AN21: 166 | AO21: 59 | AP21: 134 | AQ21: 54 | AR21: 652 | AS21: 118 | AT21: 72 | AU21: 427 | AV21: 22 | AW21: 94 | AX21: 73 | AY21: - | AZ21: 17 | BA21: 85 | BB21: 47 | BC21: 29 | BD21: - | BE21: - | BF21: - | BG21: - | BH21: 7266851 | BI21: 128 | BJ21: - | BK21: 1776201 | BL21: 10986 | BM21: - | BN21: 12 | BO21: 64264 | BP21: 492039 | BQ21: 281 | BR21: - | BS21: 1223 | BT21: 20622 | BU21: 81314 | BV21: 97283 | BW21: 52846 | BX21: 447123 | BY21: 9605509 | BZ21: - | CA21: - | CB21: - | CC21: 59 | CD21: - | CE21: - | CF21: - | CG21: - | CH21: 45 | CI21: - | CJ21: 28 | CK21: - | CL21: 55579 | CM21: 54790 | CN21: 4766 | CO21: 188 | CP21: 122 | CQ21: 125 | CR21: - | CS21: - | CT21: 17092 | CU21: - | CV21: - | CW21: - | CX21: - | CY21: - | CZ21: - | DA21: - | DB21: - | DC21: 3616 | DD21: 699322 | DE21: 127939 | DF21: - | DG21: - | DH21: - | DI21: - | DJ21: - | DK21: - | DL21: - | DM21: - | DN21: 76 | DO21: 148 | DP21: 422 | DQ21: 66 | DR21: 628 | DS21: - | DT21: - | DU21: - | DV21: - | DW21: - | DX21: - | DY21: - | DZ21: - | EA21: 18 | EB21: - | EC21: - | ED21: 85 | EE21: 96 | EF21: 31 | EG21: 177 | EH21: 30 | EI21: 1174 | EJ21: - | EK21: - | EL21: - | EM21: - | EN21: - | EO21: - | EP21: - | EQ21: - | ER21: 13294 | ES21: 1650 | ET21: 136 | EU21: 8729 | EV21: 517 | EW21: 46 | EX21: 94 | EY21: 85 | EZ21: 340 | FA21: 391 | FB21: 222 | FC21: 311117 | FD21: 2471 | FE21: 2373 | FF21: 1846246 | FG21: 5853 | FH21: 1221025 | FI21: - | FJ21: - | FK21: 1916619 | FL21: 9045890 | FM21: 4787 | FN21: 739 | FO21: 2676 | FP21: 630 | FQ21: 1767 | FR21: 150 | FS21: 28 | FT21: 1834 | FU21: 948 | FV21: - | FW21: 157456 | FX21: 260331 | FY21: 55301 | FZ21: 556392 | GA21: 26913 | GB21: 69673 | GC21: 4629333 | GD21: 1153139 | GE21: - | GF21: 246136 | GG21: 49121817 | GH21: 142640371 | GI21: - | GJ21: - | GK21: 19391580 | GL21: -2599515 | GM21: 1923299 | GN21: - | GO21: 161355735 | GP21: 210477552 | GQ21: 18901132 | GR21: - | GS21: - | GT21: 18901132 | GU21: - | GV21: - | GW21: - | GX21: - | GY21: - | GZ21: 191576420 | HA21: 210477552
B22: 17 | C22: Tanaman Biofarmaka | D22: - | E22: - | F22: - | G22: - | H22: - | I22: - | J22: - | K22: - | L22: - | M22: - | N22: - | O22: - | P22: - | Q22: - | R22: - | S22: - | T22: 16629 | U22: - | V22: - | W22: - | X22: - | Y22: - | Z22: - | AA22: - | AB22: - | AC22: - | AD22: - | AE22: - | AF22: - | AG22: - | AH22: - | AI22: - | AJ22: - | AK22: - | AL22: - | AM22: - | AN22: - | AO22: - | AP22: - | AQ22: - | AR22: - | AS22: - | AT22: - | AU22: - | AV22: - | AW22: - | AX22: - | AY22: - | AZ22: - | BA22: - | BB22: - | BC22: - | BD22: - | BE22: 20855 | BF22: - | BG22: - | BH22: 10904 | BI22: 768 | BJ22: - | BK22: 5954 | BL22: - | BM22: - | BN22: - | BO22: - | BP22: - | BQ22: 101 | BR22: - | BS22: 314 | BT22: 175 | BU22: 86708 | BV22: 471291 | BW22: - | BX22: - | BY22: 46710 | BZ22: - | CA22: - | CB22: - | CC22: - | CD22: - | CE22: - | CF22: - | CG22: - | CH22: - | CI22: - | CJ22: - | CK22: - | CL22: - | CM22: - | CN22: - | CO22: - | CP22: - | CQ22: - | CR22: - | CS22: - | CT22: - | CU22: - | CV22: - | CW22: - | CX22: - | CY22: - | CZ22: - | DA22: 52717 | DB22: - | DC22: 124401 | DD22: 243496 | DE22: 1620174 | DF22: - | DG22: - | DH22: - | DI22: - | DJ22: - | DK22: - | DL22: - | DM22: - | DN22: - | DO22: - | DP22: - | DQ22: - | DR22: - | DS22: - | DT22: - | DU22: - | DV22: - | DW22: - | DX22: - | DY22: - | DZ22: - | EA22: - | EB22: - | EC22: - | ED22: - | EE22: - | EF22: - | EG22: - | EH22: - | EI22: - | EJ22: - | EK22: - | EL22: - | EM22: - | EN22: - | EO22: - | EP22: - | EQ22: - | ER22: - | ES22: - | ET22: - | EU22: 261 | EV22: - | EW22: - | EX22: - | EY22: - | EZ22: - | FA22: - | FB22: - | FC22: - | FD22: - | FE22: - | FF22: - | FG22: - | FH22: - | FI22: - | FJ22: - | FK22: 361 | FL22: 4963 | FM22: - | FN22: - | FO22: - | FP22: - | FQ22: - | FR22: - | FS22: - | FT22: - | FU22: - | FV22: - | FW22: - | FX22: 55198 | FY22: 1392 | FZ22: 17457 | GA22: 278 | GB22: 7 | GC22: 46963 | GD22: 11738 | GE22: - | GF22: - | GG22: 2839815 | GH22: 1601670 | GI22: - | GJ22: - | GK22: 728241 | GL22: 535473 | GM22: 3918648 | GN22: - | GO22: 6784032 | GP22: 9623847 | GQ22: 739379 | GR22: - | GS22: - | GT22: 739379 | GU22: - | GV22: - | GW22: - | GX22: - | GY22: - | GZ22: 8884468 | HA22: 9623847
B23: 18 | C23: Karet | D23: - | E23: - | F23: - | G23: - | H23: - | I23: - | J23: - | K23: - | L23: - | M23: - | N23: - | O23: - | P23: - | Q23: - | R23: - | S23: - | T23: - | U23: 4670525 | V23: - | W23: - | X23: - | Y23: - | Z23: - | AA23: - | AB23: - | AC23: - | AD23: - | AE23: - | AF23: - | AG23: - | AH23: - | AI23: - | AJ23: - | AK23: - | AL23: - | AM23: - | AN23: - | AO23: - | AP23: - | AQ23: - | AR23: - | AS23: - | AT23: - | AU23: - | AV23: - | AW23: - | AX23: - | AY23: - | AZ23: - | BA23: - | BB23: - | BC23: - | BD23: - | BE23: - | BF23: - | BG23: - | BH23: - | BI23: - | BJ23: - | BK23: - | BL23: - | BM23: - | BN23: - | BO23: - | BP23: - | BQ23: - | BR23: - | BS23: - | BT23: - | BU23: - | BV23: - | BW23: - | BX23: - | BY23: - | BZ23: - | CA23: - | CB23: - | CC23: - | CD23: - | CE23: - | CF23: - | CG23: - | CH23: - | CI23: - | CJ23: - | CK23: - | CL23: - | CM23: - | CN23: - | CO23: - | CP23: - | CQ23: - | CR23: - | CS23: - | CT23: - | CU23: - | CV23: - | CW23: 3479714 | CX23: - | CY23: 851931 | CZ23: - | DA23: - | DB23: - | DC23: - | DD23: - | DE23: - | DF23: 7385763 | DG23: 43382924 | DH23: 3011102 | DI23: 2211596 | DJ23: - | DK23: - | DL23: - | DM23: - | DN23: - | DO23: - | DP23: 48599 | DQ23: - | DR23: 59838 | DS23: - | DT23: - | DU23: - | DV23: - | DW23: - | DX23: - | DY23: - | DZ23: - | EA23: - | EB23: - | EC23: - | ED23: - | EE23: - | EF23: - | EG23: - | EH23: - | EI23: 886703 | EJ23: 829126 | EK23: - | EL23: - | EM23: - | EN23: - | EO23: - | EP23: - | EQ23: - | ER23: - | ES23: - | ET23: - | EU23: - | EV23: - | EW23: - | EX23: - | EY23: 8925 | EZ23: 690 | FA23: - | FB23: - | FC23: - | FD23: - | FE23: - | FF23: - | FG23: - | FH23: - | FI23: - | FJ23: - | FK23: - | FL23: - | FM23: - | FN23: - | FO23: - | FP23: - | FQ23: - | FR23: - | FS23: - | FT23: - | FU23: - | FV23: - | FW23: - | FX23: - | FY23: - | FZ23: - | GA23: - | GB23: 2771 | GC23: - | GD23: - | GE23: - | GF23: - | GG23: 66830207 | GH23: - | GI23: - | GJ23: - | GK23: 8522818 | GL23: 4075702 | GM23: 88039 | GN23: - | GO23: 12686559 | GP23: 79516766 | GQ23: 667495 | GR23: - | GS23: - | GT23: 667495 | GU23: - | GV23: - | GW23: - | GX23: - | GY23: - | GZ23: 78849271 | HA23: 79516766
B24: 19 | C24: Kelapa | D24: - | E24: - | F24: - | G24: - | H24: - | I24: - | J24: - | K24: - | L24: - | M24: - | N24: - | O24: - | P24: - | Q24: - | R24: - | S24: - | T24: - | U24: - | V24: 905673 | W24: - | X24: - | Y24: - | Z24: - | AA24: - | AB24: - | AC24: - | AD24: - | AE24: - | AF24: - | AG24: - | AH24: - | AI24: - | AJ24: - | AK24: - | AL24: - | AM24: - | AN24: - | AO24: - | AP24: - | AQ24: - | AR24: - | AS24: - | AT24: - | AU24: - | AV24: - | AW24: - | AX24: - | AY24: - | AZ24: - | BA24: - | BB24: - | BC24: - | BD24: 39513 | BE24: - | BF24: - | BG24: - | BH24: 106 | BI24: 18746 | BJ24: 9586268 | BK24: 884063 | BL24: - | BM24: - | BN24: - | BO24: 945843 | BP24: 335 | BQ24: - | BR24: - | BS24: 1840 | BT24: - | BU24: - | BV24: 1339359 | BW24: 45765 | BX24: 50356 | BY24: 1692241 | BZ24: - | CA24: - | CB24: - | CC24: - | CD24: - | CE24: - | CF24: - | CG24: - | CH24: - | CI24: 4138 | CJ24: 23904 | CK24: - | CL24: - | CM24: - | CN24: 85210 | CO24: - | CP24: - | CQ24: - | CR24: - | CS24: - | CT24: - | CU24: 2455792 | CV24: - | CW24: - | CX24: - | CY24: - | CZ24: - | DA24: - | DB24: - | DC24: 759821 | DD24: 1231575 | DE24: 240944 | DF24: - | DG24: - | DH24: - | DI24: - | DJ24: - | DK24: - | DL24: - | DM24: - | DN24: - | DO24: - | DP24: - | DQ24: - | DR24: 15055 | DS24: - | DT24: - | DU24: - | DV24: - | DW24: - | DX24: - | DY24: - | DZ24: - | EA24: - | EB24: - | EC24: - | ED24: - | EE24: - | EF24: - | EG24: - | EH24: - | EI24: - | EJ24: 656299 | EK24: 90583 | EL24: 55643 | EM24: 18395 | EN24: - | EO24: - | EP24: - | EQ24: - | ER24: - | ES24: - | ET24: - | EU24: - | EV24: - | EW24: - | EX24: - | EY24: - | EZ24: - | FA24: - | FB24: - | FC24: - | FD24: - | FE24: - | FF24: - | FG24: - | FH24: - | FI24: - | FJ24: - | FK24: 550284 | FL24: 7519080 | FM24: - | FN24: - | FO24: - | FP24: - | FQ24: - | FR24: - | FS24: - | FT24: - | FU24: - | FV24: - | FW24: - | FX24: 43005 | FY24: 11044 | FZ24: 517 | GA24: 1406 | GB24: 23501 | GC24: 99166 | GD24: 295482 | GE24: - | GF24: 17554 | GG24: 29708506 | GH24: 8255309 | GI24: - | GJ24: - | GK24: 5989568 | GL24: -1261073 | GM24: 5079287 | GN24: - | GO24: 18063091 | GP24: 47771597 | GQ24: 90012 | GR24: - | GS24: - | GT24: 90012 | GU24: - | GV24: - | GW24: - | GX24: - | GY24: - | GZ24: 47681585 | HA24: 47771597
B25: 20 | C25: Kelapa Sawit | D25: - | E25: - | F25: - | G25: - | H25: - | I25: - | J25: - | K25: - | L25: - | M25: - | N25: - | O25: - | P25: - | Q25: - | R25: - | S25: - | T25: - | U25: - | V25: - | W25: 48870767 | X25: - | Y25: - | Z25: - | AA25: - | AB25: - | AC25: - | AD25: - | AE25: - | AF25: - | AG25: - | AH25: - | AI25: - | AJ25: - | AK25: - | AL25: - | AM25: - | AN25: - | AO25: - | AP25: - | AQ25: - | AR25: - | AS25: - | AT25: - | AU25: - | AV25: - | AW25: - | AX25: - | AY25: - | AZ25: - | BA25: - | BB25: - | BC25: - | BD25: - | BE25: - | BF25: - | BG25: - | BH25: - | BI25: 270438688 | BJ25: - | BK25: - | BL25: - | BM25: - | BN25: - | BO25: - | BP25: - | BQ25: - | BR25: - | BS25: - | BT25: - | BU25: - | BV25: - | BW25: - | BX25: - | BY25: - | BZ25: - | CA25: - | CB25: - | CC25: - | CD25: - | CE25: - | CF25: - | CG25: - | CH25: - | CI25: - | CJ25: - | CK25: - | CL25: - | CM25: - | CN25: - | CO25: - | CP25: - | CQ25: - | CR25: - | CS25: - | CT25: - | CU25: - | CV25: - | CW25: - | CX25: - | CY25: - | CZ25: - | DA25: - | DB25: - | DC25: - | DD25: - | DE25: - | DF25: - | DG25: - | DH25: - | DI25: - | DJ25: - | DK25: - | DL25: - | DM25: - | DN25: - | DO25: - | DP25: - | DQ25: - | DR25: - | DS25: - | DT25: - | DU25: - | DV25: - | DW25: - | DX25: - | DY25: - | DZ25: - | EA25: - | EB25: - | EC25: - | ED25: - | EE25: - | EF25: - | EG25: - | EH25: - | EI25: - | EJ25: - | EK25: - | EL25: - | EM25: - | EN25: - | EO25: - | EP25: - | EQ25: - | ER25: - | ES25: - | ET25: - | EU25: - | EV25: - | EW25: - | EX25: - | EY25: - | EZ25: - | FA25: - | FB25: - | FC25: - | FD25: - | FE25: - | FF25: - | FG25: - | FH25: - | FI25: - | FJ25: - | FK25: - | FL25: - | FM25: - | FN25: - | FO25: - | FP25: - | FQ25: - | FR25: - | FS25: - | FT25: - | FU25: - | FV25: - | FW25: - | FX25: - | FY25: - | FZ25: - | GA25: - | GB25: 887 | GC25: - | GD25: - | GE25: - | GF25: - | GG25: 319310342 | GH25: - | GI25: - | GJ25: - | GK25: 70072917 | GL25: -12264215 | GM25: 151280 | GN25: - | GO25: 57959982 | GP25: 377270324 | GQ25: 311 | GR25: - | GS25: - | GT25: 311 | GU25: - | GV25: - | GW25: - | GX25: - | GY25: - | GZ25: 377270013 | HA25: 377270324
B26: 21 | C26: Kopi | D26: - | E26: - | F26: - | G26: - | H26: - | I26: - | J26: - | K26: - | L26: - | M26: - | N26: - | O26: - | P26: - | Q26: - | R26: - | S26: - | T26: - | U26: - | V26: - | W26: - | X26: 4525411 | Y26: - | Z26: - | AA26: - | AB26: - | AC26: - | AD26: - | AE26: - | AF26: - | AG26: - | AH26: - | AI26: - | AJ26: - | AK26: - | AL26: - | AM26: - | AN26: - | AO26: - | AP26: - | AQ26: - | AR26: - | AS26: - | AT26: - | AU26: - | AV26: - | AW26: - | AX26: - | AY26: - | AZ26: - | BA26: - | BB26: - | BC26: - | BD26: - | BE26: - | BF26: - | BG26: - | BH26: - | BI26: - | BJ26: - | BK26: 1703462 | BL26: - | BM26: - | BN26: - | BO26: - | BP26: - | BQ26: 21303 | BR26: - | BS26: 22555784 | BT26: 1633 | BU26: - | BV26: - | BW26: - | BX26: 5283 | BY26: 1775944 | BZ26: - | CA26: - | CB26: - | CC26: - | CD26: - | CE26: - | CF26: - | CG26: - | CH26: - | CI26: - | CJ26: - | CK26: - | CL26: - | CM26: - | CN26: - | CO26: - | CP26: - | CQ26: - | CR26: - | CS26: - | CT26: - | CU26: - | CV26: - | CW26: - | CX26: - | CY26: - | CZ26: - | DA26: - | DB26: - | DC26: - | DD26: 15191 | DE26: 31958 | DF26: - | DG26: - | DH26: - | DI26: - | DJ26: - | DK26: - | DL26: - | DM26: - | DN26: - | DO26: - | DP26: - | DQ26: - | DR26: - | DS26: - | DT26: - | DU26: - | DV26: - | DW26: - | DX26: - | DY26: - | DZ26: - | EA26: - | EB26: - | EC26: - | ED26: - | EE26: - | EF26: - | EG26: - | EH26: - | EI26: - | EJ26: - | EK26: - | EL26: - | EM26: - | EN26: - | EO26: - | EP26: - | EQ26: - | ER26: - | ES26: - | ET26: - | EU26: - | EV26: - | EW26: - | EX26: - | EY26: - | EZ26: - | FA26: - | FB26: - | FC26: - | FD26: - | FE26: - | FF26: - | FG26: - | FH26: - | FI26: - | FJ26: - | FK26: 166965 | FL26: 4275410 | FM26: - | FN26: - | FO26: - | FP26: - | FQ26: - | FR26: - | FS26: - | FT26: - | FU26: - | FV26: - | FW26: - | FX26: - | FY26: 4416 | FZ26: - | GA26: - | GB26: 128 | GC26: - | GD26: - | GE26: - | GF26: - | GG26: 35082888 | GH26: - | GI26: - | GJ26: - | GK26: 2369997 | GL26: 5008362 | GM26: 8588744 | GN26: - | GO26: 15967103 | GP26: 51049991 | GQ26: 485504 | GR26: - | GS26: - | GT26: 485504 | GU26: - | GV26: - | GW26: - | GX26: - | GY26: - | GZ26: 50564487 | HA26: 51049991
B27: 22 | C27: Teh | D27: - | E27: - | F27: - | G27: - | H27: - | I27: - | J27: - | K27: - | L27: - | M27: - | N27: - | O27: - | P27: - | Q27: - | R27: - | S27: - | T27: - | U27: - | V27: - | W27: - | X27: - | Y27: 41599 | Z27: - | AA27: - | AB27: - | AC27: - | AD27: - | AE27: - | AF27: - | AG27: - | AH27: - | AI27: - | AJ27: - | AK27: - | AL27: - | AM27: - | AN27: - | AO27: - | AP27: - | AQ27: - | AR27: - | AS27: - | AT27: - | AU27: - | AV27: - | AW27: - | AX27: - | AY27: - | AZ27: - | BA27: - | BB27: - | BC27: - | BD27: - | BE27: - | BF27: - | BG27: - | BH27: - | BI27: - | BJ27: - | BK27: 46636 | BL27: - | BM27: - | BN27: - | BO27: - | BP27: - | BQ27: 256 | BR27: - | BS27: - | BT27: 6416630 | BU27: - | BV27: - | BW27: - | BX27: 140 | BY27: 31373 | BZ27: - | CA27: - | CB27: - | CC27: - | CD27: - | CE27: - | CF27: - | CG27: - | CH27: - | CI27: - | CJ27: - | CK27: - | CL27: - | CM27: - | CN27: - | CO27: - | CP27: - | CQ27: - | CR27: - | CS27: - | CT27: - | CU27: - | CV27: - | CW27: - | CX27: - | CY27: - | CZ27: - | DA27: - | DB27: - | DC27: - | DD27: 97 | DE27: 195 | DF27: - | DG27: - | DH27: - | DI27: - | DJ27: - | DK27: - | DL27: - | DM27: - | DN27: - | DO27: - | DP27: - | DQ27: - | DR27: - | DS27: - | DT27: - | DU27: - | DV27: - | DW27: - | DX27: - | DY27: - | DZ27: - | EA27: - | EB27: - | EC27: - | ED27: - | EE27: - | EF27: - | EG27: - | EH27: - | EI27: - | EJ27: - | EK27: - | EL27: - | EM27: - | EN27: - | EO27: - | EP27: - | EQ27: - | ER27: - | ES27: - | ET27: - | EU27: - | EV27: - | EW27: - | EX27: - | EY27: - | EZ27: - | FA27: - | FB27: - | FC27: - | FD27: - | FE27: - | FF27: - | FG27: - | FH27: - | FI27: - | FJ27: - | FK27: - | FL27: 383 | FM27: - | FN27: - | FO27: - | FP27: - | FQ27: - | FR27: - | FS27: - | FT27: - | FU27: - | FV27: - | FW27: - | FX27: - | FY27: - | FZ27: - | GA27: - | GB27: - | GC27: - | GD27: - | GE27: - | GF27: - | GG27: 6537309 | GH27: - | GI27: - | GJ27: - | GK27: 90971 | GL27: 205284 | GM27: 184150 | GN27: - | GO27: 480405 | GP27: 7017714 | GQ27: 114481 | GR27: - | GS27: - | GT27: 114481 | GU27: - | GV27: - | GW27: - | GX27: - | GY27: - | GZ27: 6903233 | HA27: 7017714
B28: 23 | C28: Kakao | D28: - | E28: - | F28: - | G28: - | H28: - | I28: - | J28: - | K28: - | L28: - | M28: - | N28: - | O28: - | P28: - | Q28: - | R28: - | S28: - | T28: - | U28: - | V28: - | W28: - | X28: - | Y28: - | Z28: 1184029 | AA28: - | AB28: - | AC28: - | AD28: - | AE28: - | AF28: - | AG28: - | AH28: - | AI28: - | AJ28: - | AK28: - | AL28: - | AM28: - | AN28: - | AO28: - | AP28: - | AQ28: - | AR28: - | AS28: - | AT28: - | AU28: - | AV28: - | AW28: - | AX28: - | AY28: - | AZ28: - | BA28: - | BB28: - | BC28: - | BD28: - | BE28: - | BF28: - | BG28: - | BH28: - | BI28: 585288 | BJ28: - | BK28: 4091279 | BL28: - | BM28: - | BN28: - | BO28: - | BP28: - | BQ28: 11781162 | BR28: - | BS28: 3403562 | BT28: 3286256 | BU28: - | BV28: 2811213 | BW28: 897484 | BX28: 160588 | BY28: 10838869 | BZ28: - | CA28: - | CB28: - | CC28: - | CD28: - | CE28: - | CF28: - | CG28: - | CH28: - | CI28: - | CJ28: - | CK28: - | CL28: - | CM28: - | CN28: - | CO28: - | CP28: - | CQ28: - | CR28: - | CS28: - | CT28: - | CU28: - | CV28: - | CW28: - | CX28: - | CY28: - | CZ28: - | DA28: 587253 | DB28: 282575 | DC28: 449044 | DD28: 681069 | DE28: 337521 | DF28: - | DG28: - | DH28: - | DI28: - | DJ28: - | DK28: - | DL28: - | DM28: - | DN28: - | DO28: - | DP28: - | DQ28: - | DR28: - | DS28: - | DT28: - | DU28: - | DV28: - | DW28: - | DX28: - | DY28: - | DZ28: - | EA28: - | EB28: - | EC28: - | ED28: - | EE28: - | EF28: - | EG28: - | EH28: - | EI28: - | EJ28: - | EK28: - | EL28: - | EM28: - | EN28: - | EO28: - | EP28: - | EQ28: - | ER28: - | ES28: - | ET28: - | EU28: - | EV28: - | EW28: - | EX28: - | EY28: - | EZ28: - | FA28: - | FB28: - | FC28: - | FD28: - | FE28: - | FF28: - | FG28: - | FH28: - | FI28: - | FJ28: - | FK28: - | FL28: 162762 | FM28: - | FN28: - | FO28: - | FP28: - | FQ28: - | FR28: - | FS28: - | FT28: - | FU28: - | FV28: - | FW28: - | FX28: - | FY28: 4772 | FZ28: - | GA28: - | GB28: - | GC28: - | GD28: - | GE28: - | GF28: - | GG28: 41544726 | GH28: - | GI28: - | GJ28: - | GK28: 8477131 | GL28: 10662308 | GM28: 652470 | GN28: - | GO28: 19791909 | GP28: 61336635 | GQ28: 7724253 | GR28: - | GS28: - | GT28: 7724253 | GU28: - | GV28: - | GW28: - | GX28: - | GY28: - | GZ28: 53612382 | HA28: 61336635
